Workbook

Sheet 1. Directions

Sheet 2. Income
L3: Job /position | M3: Chemical Engineer
L4: City | M4: Cleveland
L5: State | M5: Ohio
L6: Source of information | M6: payscale.com
L9: Annual Salary | M9: 84307
L10: Plus: Other earned income (if any) | M10: 0
L11: Total income for the year | M11: =M9+M10 -> 84307
L12: Divide by 12 | M12: 12
L13: Monthly income for a budget | M13: =M11/M12 -> 7025.5833

Sheet 3. FICA tax
L3: Annual salary, if BELOW $176,100 | M3: ='2. Income'!M9 -> 84307
L4: FICA rate | M4: 0.0765
L5: Total FICA Tax | M5: =M3*M4 -> 6449.4855
L6: divide by 12 | M6: 12
L7: Monthly FICA tax for budget | M7: =M5/M6 -> 537.45713
L10: Annual salary, if ABOVE $176,100
L11: Less social security cap | M11: =B21 -> 147000
L12: Excess over cap | M12: =M10-M11 -> -147000
L13: Medicare tax rate on excess | M13: 0.0145
L14: Medicare tax on excess
L15: Plus:
L16: Social security cap | M16: =B21 -> 147000
L17: FICA tax rate | M17: =M4 -> 0.0765
L18: FICA on salary up to cap | M18: =M16*M17 -> 11245.5
L20: Total FICA tax (SS and Medicare) | M20: =M14+M18 -> 11245.5
A21: 2022 SS Wage cap | B21: 147000 | L21: divide by 12 | M21: 12
L22: Monthly FICA tax for budget
L25: Any self-employment income? | M25: 0
L26: If so, calculate double the FICA rate on it | M26: 0
L27: divide by 12 | M27: 12
L28: Monthly FICA on self-employed income | M28: 0
L29: Plus monthly FICA on salary (above) | M29: =M28+M7 -> 537.45713
L30: Total monthly FICA for budget | M30: =M29 -> 537.45713

Sheet 4. Local income tax
F2: Will you have a local income tax? | G2: yes
F4: Annual earned income | G4: ='2. Income'!M9 -> 84307
F5: Local income tax rate | G5: 0.025
F6: Total yearly local income tax | G6: =G4*G5 -> 2107.675
F7: -OR-
F8: Total flat dollar amount per year | G8: 0
F10: Divide by 12 | G10: 12
F11: Monthly local income tax for budget | G11: =G6/G10 -> 175.63958
B27: https://www.ritaohio.com/municipalities
B29: http://ccatax.ci.cleveland.oh.us/?p=taxrates
B31: https://taxfoundation.org/local-income-taxes-2019/

Sheet 5. Retirement contributions
M4: Step 1:
M5: Advised amount:
M6: Annual salary | N6: ='2. Income'!M9 -> 84307
M7: 10% of salary | N7: =0.1*N6 -> 8430.7
M8: 15% of salary | N8: =0.15*N6 -> 12646.05
M10: Step 2:
M11: Decision: | N11: Per year
M12: Total amount you want to contribute | N12: =AVERAGE(N7,N8) -> 10538.375
M13: Of total amount, how much to traditional 401K? | N13: =N12-N15-N16-2000 -> 1538.375
M14: Of total amount, how much to ROTH 401K? | N14: =N12-N13-N15-N16 -> 2000
M15: Of total amount, how much to traditional IRA? | N15: 3000
M16: Of total amount, how much to ROTH IRA? | N16: 4000
M18: Divide by 12 to get the amounts for your budget
M19: Traditional 401k monthly contribution | N19: =N13/12 -> 128.19792
M20: ROTH 401k monthly contribution | N20: =N14/12 -> 166.66667
M21: Traditional IRA monthly contribution | N21: =N15/12 -> 250
M22: ROTH IRA monthly contribution | N22: =N16/12 -> 333.33333

Sheet 6. Federal Taxes
G2: Step 1: Calculate taxable income | H2: TOTAL FOR YEAR
G3: Annual Income | H3: ='2. Income'!M9 -> 84307
G4: Less: Total contributions to Traditional 401(k) (no deduction for a Roth) | H4: ='5. Retirement contributions'!N13 -> 1538.375
G5: Less: Total contribution to Traditional IRA (no deduction for a Roth!) | H5: ='5. Retirement contributions'!N15 -> 3000
G6: Less: Interest on Student Loan ($2,500 max) subject to income limit | H6: =B37 -> 274.82
G7: Adjusted Gross Income (AGI) | H7: =H3-H4-H5-H6 -> 79493.805
G8: Less: Standard Deduction (Single taxpayer) | H8: 12950
G9: Taxable income | H9: =H7-H8 -> 66543.805
G13: Step 2: Calculate income tax
G14: 2022 Tax Brackets: Find the ONE bracket your taxable income (above) falls within | H14: Then federal tax due is…. | I14: Calculate YOUR Federal tax
G15: $0-$10,275 | H15: 10% of taxable income | I15: n/a
G16: $10,275-$41,775 | H16: $1,027 + 12% of the taxable income over $10,275 | I16: n/a
G17: $41,775- $89,075 | H17: $4,807 + 22% of the taxable income over $41,775 | I17: =(H9-41775)*0.22+4807 -> 10256.137
G18: $89,075- $170,050 | H18: $15,213 + 24% of the taxable income over $89,075 | I18: n/a
G19: $170,050-$215,950 | H19: $34,647 + 32% of the taxable income over $170,050 | I19: n/a
G20: $215,950- $539,900 | H20: $49,335 + 35% of the taxable income over $215,950 | I20: n/a
G21: Over $539,900 | H21: $162,718+ 37% of the taxable income over $539,900 | I21: n/a
H23: Step 3: Divide by 12 to for monthly budget | I23: =I17/12 -> 854.67809
A35: Total student loan balance | B35: 6500
A36: Average Interest Rate (see below) | B36: 0.04228 | C36: from life app
A37: Student loan interest | B37: =B35*B36 -> 274.82
A40: FEDERAL STUDENT LOAN INTEREST RATES (Based on year they were given):

Sheet 7. State taxes
I2: Step 1:
I3: What state will you live in? | J3: Ohio
I4: Do they have income tax? | J4: Yes
I6: Step 2: ONLY IF OHIO
I8: AGI from federal taxes worksheet cell H7 | J8: ='6. Federal Taxes'!H7 -> 79493.805
I9: Less: personal exemption | J9: 2100
I10: Ohio Taxable income | J10: =J8-J9 -> 77393.805
I13: 2023 Tax brackets: Ohio Taxable Income | J13: Tax Calculation | K13: =J10 -> 77393.805
I14: 0 - $26,050 | J14: 0 | K14: n/a
I15: $26,050- $100,000 | J15: $360.59 + 2.75% of excess over $26,050 | K15: =360.59+0.0275*(J10-26050) -> 1772.5446
I16: $100,000- $115,300 | J16: #2,394.32+ 3.668% of excess over $100,000 | K16: n/a
I17: Over $115,300 | J17: $2,958.58 + 3.75% of excess over $115,300 | K17: n/a
J19: Divided by 12 | K19: 12
J20: State income tax for a monthly budget | K20: =K15/12 -> 147.71205
I22: Step 3: ONLY IF OTHER STATE
I24: AGI from federal taxes
I25: Less: state standard deduction (if any)
I26: Less: state personal exemption (if any)
I27: State Taxable income
I29: State income tax per calculations
I30: Divided by 12 | J30: 12
I31: State income tax for monthly budget
A36: https://taxfoundation.org/publications/state-individual-income-tax-rates-and-brackets/
A38: Paste the Brackets and Rates here | E38: Income Layer | F38: Tax on layer
A52: EXAMPLE: Assume $60,000 of state taxable income (cell J29) and the following tax brackets
A54: Paste the Brackets and Rates here | E54: Income Layer | F54: Tax on layer
A55: 0.01 | B55: > | C55: 0 | E55: =C56-C55 -> 8932 | F55: =E55*A55 -> 89.32
A56: 0.02 | B56: > | C56: 8932 | E56: =C57-C56 -> 12243 | F56: =E56*A56 -> 244.86
A57: 0.04 | B57: > | C57: 21175 | E57: =C58-C57 -> 12246 | F57: =E57*A57 -> 489.84
A58: 0.06 | B58: > | C58: 33421 | E58: =C59-C58 -> 12973 | F58: =E58*A58 -> 778.38
A59: 0.08 | B59: > | C59: 46394 | E59: =C60-C59 -> 12240 | F59: =E59*A59 -> 979.2
A60: 0.093 | B60: > | C60: 58634 | E60: =60000-(E55+E56+E57+E58+E59) -> 1366 | F60: =E60*A60 -> 127.038
A61: 0.103 | B61: > | C61: 299508 | E61: =SUM(E55:E60) -> 60000 | F61: =SUM(F55:F60) -> 2708.638
A62: 0.113 | B62: > | C62: 359407
A63: 0.123 | B63: > | C63: 599012
A64: 0.133 | B64: > | C64: 1000000

Sheet 8. Health insurance
N3: SELF-EMPLOYED? (yes or no) | O3: no
N4: Type of Plan or Average | O4: All (Average)
N5: Annual cost | O5: 1368
N6: Divide by 12 | O6: 12
N7: Amount for monthly budget | O7: =O5/O6 -> 114
N8: -OR-
N9: My parents will keep paying | O9: yes
A30: Link to information:
A32: https://www.kff.org/health-costs/report/2022-employer-health-benefits-survey/

Sheet 9. Summary 
A1: MONTHLY INCOME SUMMARY
B2: MONTHLY
A3: Monthly Income:
A4: Salary and Wages (From Tab 2) | B4: ='2. Income'!M13 -> 7025.5833
A5: Interest/Dividends (From Tab 2 if any) | B5: 0
A6: Other income (from Tab 2, specify) | B6: 0
A7: Total Monthly Gross Income | B7: =SUM(B3:B6) -> 7025.5833
A9: Retirement Contributions: (From Tab 5)
A10: Traditional 401(k) | B10: ='5. Retirement contributions'!N19 -> 128.19792
A11: ROTH 401(k) | B11: ='5. Retirement contributions'!N20 -> 166.66667
A12: Traditional IRA | B12: ='5. Retirement contributions'!N21 -> 250
A13: ROTH IRA | B13: ='5. Retirement contributions'!N22 -> 333.33333
A14: Total Retirement Savings | B14: =SUM(B10:B13) -> 878.19792
A16: Deductions:
A17: Health Insurance (From Tab 8) | B17: 0 | C17: Parents coverage
A19: Taxes:
A20: FICA (From Tab 3) | B20: ='3. FICA tax'!M30 -> 537.45713
A21: Local Income Tax (From Tab 4) | B21: ='4. Local income tax'!G11 -> 175.63958
A22: State Income Tax (From Tab 7) | B22: ='7. State taxes'!K20 -> 147.71205
A23: Federal Income Tax (From Tab 6) | B23: ='6. Federal Taxes'!I23 -> 854.67809
A24: Total Taxes | B24: =SUM(B20:B23) -> 1715.4869
A26: Summary - Monthly Cash Flows
A27: Gross Monthly Income | B27: =B7 -> 7025.5833
A28: After Tax Monthly Income | B28: =B7-B24 -> 5310.0965
A29: After Taxes, Deductions, and Retirement Savings Cash Flow | B29: =B7-B14-B17-B24 -> 4431.8986

Sheet Grading Rubric
A1: Worksheet | B1: Points
A2: 1. Goals | B2: 10
A3: Short term goals
A4: Midrange goals
A5: Long term goals
A6: Spelling, grammar, punctuation
A7: 2. Income | B7: 5
A8: Position/job
A9: City/state
A10: Source
A11: Salary (reasonable)
A12: Other income, if any, explained
A13: Formula for monthly amount
A14: Agrees to monthly budget (cell reference)
A15: 3. FICA | B15: 5
A16: Salary cell referenced
A17: Calculation of FICA tax
A18: Agrees to monthly budget (cell reference)
A19: 4. Local income tax | B19: 5
A20: Correct about having a local tax?
A21: Correct calculation
A22: Agrees to monthly budget (cell reference)
A23: 5. Retirement contributions | B23: 10
A24: Calculation of 10% and 15% guidelines
A25: Agrees to monthly budget (401k)
A26: Agrees to monthly budget (Roth)
A27: Agrees to monthly budget (IRA)
A28: 6. Federal income tax | B28: 15
A29: Cell reference income
A30: Cell reference 401k (if any)
A31: Cell reference IRA (if any)
A32: Calculation of student loan interest (if any)
A33: Cell reference sturdent loan interest (if any)
A34: Taxable income formula
A35: Income tax calculation correct
A36: Formula for monthly amount
A37: Agrees to monthly budget (cell reference)
A38: 7. State income tax | B38: 5
A39: Step 1 completed correctly?
A40: Step 2 or 3 completed and correct
...
